2018-07-14 15:20:05,895 ERROR: Exception on /favicon.ico [GET] [in /home/mycroft/microblog/venv/lib/python3.5/site-packages/flask/app.py:1761]
Traceback (most recent call last):
  File "/home/mycroft/microblog/venv/lib/python3.5/site-packages/flask/app.py", line 1813, in full_dispatch_request
    rv = self.dispatch_request()
  File "/home/mycroft/microblog/venv/lib/python3.5/site-packages/flask/app.py", line 1791, in dispatch_request
    self.raise_routing_exception(req)
  File "/home/mycroft/microblog/venv/lib/python3.5/site-packages/flask/app.py", line 1774, in raise_routing_exception
    raise request.routing_exception
  File "/home/mycroft/microblog/venv/lib/python3.5/site-packages/flask/ctx.py", line 336, in match_request
    self.url_adapter.match(return_rule=True)
  File "/home/mycroft/microblog/venv/lib/python3.5/site-packages/werkzeug/routing.py", line 1581, in match
    raise NotFound()
werkzeug.exceptions.NotFound: 404 Not Found: The requested URL was not found on the server.  If you entered the URL manually please check your spelling and try again.

During handling of the above exception, another exception occurred:

Traceback (most recent call last):
  File "/home/mycroft/microblog/venv/lib/python3.5/site-packages/flask/app.py", line 2292, in wsgi_app
    response = self.full_dispatch_request()
  File "/home/mycroft/microblog/venv/lib/python3.5/site-packages/flask/app.py", line 1815, in full_dispatch_request
    rv = self.handle_user_exception(e)
  File "/home/mycroft/microblog/venv/lib/python3.5/site-packages/flask/app.py", line 1713, in handle_user_exception
    return self.handle_http_exception(e)
  File "/home/mycroft/microblog/venv/lib/python3.5/site-packages/flask/app.py", line 1644, in handle_http_exception
    return handler(e)
  File "/home/mycroft/microblog/app/errors.py", line 6, in not_found_error
    return render_template('404.html'), 404
  File "/home/mycroft/microblog/venv/lib/python3.5/site-packages/flask/templating.py", line 134, in render_template
    return _render(ctx.app.jinja_env.get_or_select_template(template_name_or_list),
  File "/home/mycroft/microblog/venv/lib/python3.5/site-packages/jinja2/environment.py", line 869, in get_or_select_template
    return self.get_template(template_name_or_list, parent, globals)
  File "/home/mycroft/microblog/venv/lib/python3.5/site-packages/jinja2/environment.py", line 830, in get_template
    return self._load_template(name, self.make_globals(globals))
  File "/home/mycroft/microblog/venv/lib/python3.5/site-packages/jinja2/environment.py", line 804, in _load_template
    template = self.loader.load(self, name, globals)
  File "/home/mycroft/microblog/venv/lib/python3.5/site-packages/jinja2/loaders.py", line 125, in load
    code = environment.compile(source, name, filename)
  File "/home/mycroft/microblog/venv/lib/python3.5/site-packages/jinja2/environment.py", line 591, in compile
    self.handle_exception(exc_info, source_hint=source_hint)
  File "/home/mycroft/microblog/venv/lib/python3.5/site-packages/jinja2/environment.py", line 780, in handle_exception
    reraise(exc_type, exc_value, tb)
  File "/home/mycroft/microblog/venv/lib/python3.5/site-packages/jinja2/_compat.py", line 37, in reraise
    raise value.with_traceback(tb)
  File "/home/mycroft/microblog/app/templates/404.html", line 6, in template
    {% endblock %
  File "/home/mycroft/microblog/venv/lib/python3.5/site-packages/jinja2/environment.py", line 497, in _parse
    return Parser(self, source, name, encode_filename(filename)).parse()
  File "/home/mycroft/microblog/venv/lib/python3.5/site-packages/jinja2/parser.py", line 901, in parse
    result = nodes.Template(self.subparse(), lineno=1)
  File "/home/mycroft/microblog/venv/lib/python3.5/site-packages/jinja2/parser.py", line 888, in subparse
    self.stream.expect('block_end')
  File "/home/mycroft/microblog/venv/lib/python3.5/site-packages/jinja2/lexer.py", line 384, in expect
    self.name, self.filename)
jinja2.exceptions.TemplateSyntaxError: expected token 'end of statement block', got '%'
2018-07-14 15:20:05,917 ERROR: Exception on /favicon.ico [GET] [in /home/mycroft/microblog/venv/lib/python3.5/site-packages/flask/app.py:1761]
Traceback (most recent call last):
  File "/home/mycroft/microblog/venv/lib/python3.5/site-packages/flask/app.py", line 1813, in full_dispatch_request
    rv = self.dispatch_request()
  File "/home/mycroft/microblog/venv/lib/python3.5/site-packages/flask/app.py", line 1791, in dispatch_request
    self.raise_routing_exception(req)
  File "/home/mycroft/microblog/venv/lib/python3.5/site-packages/flask/app.py", line 1774, in raise_routing_exception
    raise request.routing_exception
  File "/home/mycroft/microblog/venv/lib/python3.5/site-packages/flask/ctx.py", line 336, in match_request
    self.url_adapter.match(return_rule=True)
  File "/home/mycroft/microblog/venv/lib/python3.5/site-packages/werkzeug/routing.py", line 1581, in match
    raise NotFound()
werkzeug.exceptions.NotFound: 404 Not Found: The requested URL was not found on the server.  If you entered the URL manually please check your spelling and try again.

During handling of the above exception, another exception occurred:

Traceback (most recent call last):
  File "/home/mycroft/microblog/venv/lib/python3.5/site-packages/flask/app.py", line 2292, in wsgi_app
    response = self.full_dispatch_request()
  File "/home/mycroft/microblog/venv/lib/python3.5/site-packages/flask/app.py", line 1815, in full_dispatch_request
    rv = self.handle_user_exception(e)
  File "/home/mycroft/microblog/venv/lib/python3.5/site-packages/flask/app.py", line 1713, in handle_user_exception
    return self.handle_http_exception(e)
  File "/home/mycroft/microblog/venv/lib/python3.5/site-packages/flask/app.py", line 1644, in handle_http_exception
    return handler(e)
  File "/home/mycroft/microblog/app/errors.py", line 6, in not_found_error
    return render_template('404.html'), 404
  File "/home/mycroft/microblog/venv/lib/python3.5/site-packages/flask/templating.py", line 134, in render_template
    return _render(ctx.app.jinja_env.get_or_select_template(template_name_or_list),
  File "/home/mycroft/microblog/venv/lib/python3.5/site-packages/jinja2/environment.py", line 869, in get_or_select_template
    return self.get_template(template_name_or_list, parent, globals)
  File "/home/mycroft/microblog/venv/lib/python3.5/site-packages/jinja2/environment.py", line 830, in get_template
    return self._load_template(name, self.make_globals(globals))
  File "/home/mycroft/microblog/venv/lib/python3.5/site-packages/jinja2/environment.py", line 804, in _load_template
    template = self.loader.load(self, name, globals)
  File "/home/mycroft/microblog/venv/lib/python3.5/site-packages/jinja2/loaders.py", line 125, in load
    code = environment.compile(source, name, filename)
  File "/home/mycroft/microblog/venv/lib/python3.5/site-packages/jinja2/environment.py", line 591, in compile
    self.handle_exception(exc_info, source_hint=source_hint)
  File "/home/mycroft/microblog/venv/lib/python3.5/site-packages/jinja2/environment.py", line 780, in handle_exception
    reraise(exc_type, exc_value, tb)
  File "/home/mycroft/microblog/venv/lib/python3.5/site-packages/jinja2/_compat.py", line 37, in reraise
    raise value.with_traceback(tb)
  File "/home/mycroft/microblog/app/templates/404.html", line 6, in template
    {% endblock %
  File "/home/mycroft/microblog/venv/lib/python3.5/site-packages/jinja2/environment.py", line 497, in _parse
    return Parser(self, source, name, encode_filename(filename)).parse()
  File "/home/mycroft/microblog/venv/lib/python3.5/site-packages/jinja2/parser.py", line 901, in parse
    result = nodes.Template(self.subparse(), lineno=1)
  File "/home/mycroft/microblog/venv/lib/python3.5/site-packages/jinja2/parser.py", line 888, in subparse
    self.stream.expect('block_end')
  File "/home/mycroft/microblog/venv/lib/python3.5/site-packages/jinja2/lexer.py", line 384, in expect
    self.name, self.filename)
jinja2.exceptions.TemplateSyntaxError: expected token 'end of statement block', got '%'
2018-07-14 15:22:32,082 INFO: Microblog startup [in /home/mycroft/microblog/app/__init__.py:48]
2018-07-14 15:44:19,623 INFO: Microblog startup [in /home/mycroft/microblog/app/__init__.py:49]
